Workbook

Sheet Pages
A1: Phase | B1: Module | C1: Section # | D1: Page name | E1: Page type | F1: URL | G1: SEO title | H1: SEO title done? | I1: SEO description | J1: SEO desc done? | K1: Title chars | L1: Desc chars | M1: Content created? | N1: Content QA'd? | O1: Final result
D2: Adobe Analytics Glossary | E2: Glossary | F2: /adobe-analytics-learning/glossary/ | G2: Adobe Analytics Glossary of Terms | H2: Yes | I2: Plain-language definitions of Adobe Analytics terms: props, eVars, events, dimensions, metrics, segments, and the rest of the vocabulary. | J2: Yes | K2: 33 | L2: 137 | M2: No | N2: No | O2: =IF(AND(H2="Yes",J2="Yes",M2="Yes",N2="Yes"),"Yes","No")
D3: Adobe Analytics Learning | E3: Home | F3: /adobe-analytics-learning/ | G3: Adobe Analytics: A Practitioner's Learning Guide | H3: Yes | I3: A practitioner's guide to Adobe Analytics: not what the buttons do, but why the features exist, how they fit together, and where the traps are. | J3: Yes | K3: 48 | L3: 143 | M3: Yes | N3: Yes | O3: =IF(AND(H3="Yes",J3="Yes",M3="Yes",N3="Yes"),"Yes","No")
A4: Foundations | D4: Start with the foundations | E4: Category landing | F4: /adobe-analytics-learning/foundations/ | G4: Adobe Analytics Foundations | H4: Yes | I4: What Adobe Analytics is, where its data lands, and which variables carry that data. Everything later in this curriculum rests on these three. | J4: Yes | K4: 27 | L4: 141 | M4: No | N4: No | O4: =IF(AND(H4="Yes",J4="Yes",M4="Yes",N4="Yes"),"Yes","No")
A5: Foundations | B5: adobe-analytics-fundamentals | D5: Adobe Analytics Fundamentals | E5: Module landing | F5: /adobe-analytics-learning/foundations/adobe-analytics-fundamentals/ | G5: Adobe Analytics Fundamentals | H5: Yes | I5: What Adobe Analytics actually is, why it exists when you already have server logs and a CRM, and how the pieces fit together. | J5: Yes | K5: 28 | L5: 125 | M5: No | N5: No | O5: =IF(AND(H5="Yes",J5="Yes",M5="Yes",N5="Yes"),"Yes","No")
A6: Foundations | B6: adobe-analytics-fundamentals | C6: 1 | D6: What Is Adobe Analytics | E6: Section | F6: /adobe-analytics-learning/foundations/adobe-analytics-fundamentals/what-is-adobe-analytics/ | G6: What Is Adobe Analytics? A Practitioner's Introduction | H6: Yes | I6: What Adobe Analytics is, why it exists when you already have server logs and a CRM, and what it actually does for you. | J6: Yes | K6: 54 | L6: 118 | M6: Yes | N6: Yes | O6: =IF(AND(H6="Yes",J6="Yes",M6="Yes",N6="Yes"),"Yes","No")
A7: Foundations | B7: adobe-analytics-fundamentals | C7: 2 | D7: Adobe Analytics Ecosystem | E7: Section | F7: /adobe-analytics-learning/foundations/adobe-analytics-fundamentals/adobe-analytics-ecosystem/ | G7: The Adobe Analytics Ecosystem Explained | H7: Yes | I7: Adobe Analytics is not one tool but an ecosystem. What each piece does, which two you meet first, and how they fit together. | J7: Yes | K7: 39 | L7: 124 | M7: Yes | N7: Yes | O7: =IF(AND(H7="Yes",J7="Yes",M7="Yes",N7="Yes"),"Yes","No")
A8: Foundations | B8: adobe-analytics-fundamentals | C8: 3 | D8: Key Terminology | E8: Section | F8: /adobe-analytics-learning/foundations/adobe-analytics-fundamentals/key-terminology/ | G8: Adobe Analytics Terminology: Dimensions, Metrics, eVars | H8: Yes | I8: Dimensions, metrics, hits, visits, and visitors. The vocabulary you need first, and the eVar-versus-prop distinction that people consistently get wrong. | J8: Yes | K8: 55 | L8: 152 | M8: Yes | N8: Yes | O8: =IF(AND(H8="Yes",J8="Yes",M8="Yes",N8="Yes"),"Yes","No")
A9: Foundations | B9: adobe-analytics-fundamentals | C9: 4 | D9: Adobe Analytics vs Google Analytics | E9: Section | F9: /adobe-analytics-learning/foundations/adobe-analytics-fundamentals/adobe-analytics-vs-google-analytics/ | G9: Adobe Analytics vs Google Analytics Compared | H9: Yes | I9: How Adobe Analytics compares with Google Analytics and the rest of the market, and the data model difference that drives every other difference. | J9: Yes | K9: 44 | L9: 144 | M9: Yes | N9: Yes | O9: =IF(AND(H9="Yes",J9="Yes",M9="Yes",N9="Yes"),"Yes","No")
A10: Foundations | B10: adobe-analytics-fundamentals | C10: 5 | D10: Account Structure and Access | E10: Section | F10: /adobe-analytics-learning/foundations/adobe-analytics-fundamentals/account-structure-access/ | G10: Adobe Analytics Account Structure and Access | H10: Yes | I10: Organizations, product profiles, and permissions. How access is really controlled in Adobe Analytics, and what a product profile actually governs. | J10: Yes | K10: 44 | L10: 146 | M10: Yes | N10: Yes | O10: =IF(AND(H10="Yes",J10="Yes",M10="Yes",N10="Yes"),"Yes","No")
A11: Foundations | B11: report-suites | D11: Report Suites | E11: Module landing | F11: /adobe-analytics-learning/foundations/report-suites/ | G11: Report Suites in Adobe Analytics | H11: Yes | I11: Report suites are the boxes your data lands in. How many you need, how to configure them, and the choices you cannot undo later. | J11: Yes | K11: 32 | L11: 128 | M11: No | N11: No | O11: =IF(AND(H11="Yes",J11="Yes",M11="Yes",N11="Yes"),"Yes","No")
A12: Foundations | B12: report-suites | C12: 1 | D12: What Are Report Suites | E12: Section | F12: /adobe-analytics-learning/foundations/report-suites/what-are-report-suites/ | G12: What Are Report Suites in Adobe Analytics? | H12: Yes | I12: What a report suite is, what defines one, and the first architectural question every implementation has to answer: how many boxes do you need? | J12: Yes | K12: 42 | L12: 142 | M12: Yes | N12: Yes | O12: =IF(AND(H12="Yes",J12="Yes",M12="Yes",N12="Yes"),"Yes","No")
A13: Foundations | B13: report-suites | C13: 2 | D13: Global vs Individual Report Suites | E13: Section | F13: /adobe-analytics-learning/foundations/report-suites/global-vs-individual-report-suites/ | G13: Global vs Individual Report Suites | H13: Yes | I13: One global report suite, or a separate suite per business unit? The trade-offs, and how to give every team its own view without splitting the archive. | J13: Yes | K13: 34 | L13: 150 | M13: Yes | N13: Yes | O13: =IF(AND(H13="Yes",J13="Yes",M13="Yes",N13="Yes"),"Yes","No")
A14: Foundations | B14: report-suites | C14: 3 | D14: Virtual Report Suites | E14: Section | F14: /adobe-analytics-learning/foundations/report-suites/virtual-report-suites/ | G14: Virtual Report Suites (VRS) in Adobe Analytics | H14: Yes | I14: Virtual report suites are database views for your analytics data. One suite, one differentiator, many views, and what a VRS lets you do. | J14: Yes | K14: 46 | L14: 136 | M14: Yes | N14: Yes | O14: =IF(AND(H14="Yes",J14="Yes",M14="Yes",N14="Yes"),"Yes","No")
A15: Foundations | B15: report-suites | C15: 4 | D15: Report Suite Settings | E15: Section | F15: /adobe-analytics-learning/foundations/report-suites/report-suite-settings/ | G15: Adobe Analytics Report Suite Settings | H15: Yes | I15: The report suite settings panel, explained: general account settings, internal URL filters, bot rules, and the data-quality foundation underneath them. | J15: Yes | K15: 37 | L15: 151 | M15: Yes | N15: Yes | O15: =IF(AND(H15="Yes",J15="Yes",M15="Yes",N15="Yes"),"Yes","No")
A16: Foundations | B16: report-suites | C16: 5 | D16: Multi-Suite Tagging | E16: Section | F16: /adobe-analytics-learning/foundations/report-suites/multi-suite-tagging/ | G16: Multi-Suite Tagging in Adobe Analytics | H16: Yes | I16: Sending one hit to several report suites at once. When multi-suite tagging is right, when a virtual report suite is cheaper, and how to choose. | J16: Yes | K16: 38 | L16: 143 | M16: Yes | N16: Yes | O16: =IF(AND(H16="Yes",J16="Yes",M16="Yes",N16="Yes"),"Yes","No")
A17: Foundations | B17: report-suites | C17: 6 | D17: Bot Filtering | E17: Section | F17: /adobe-analytics-learning/foundations/report-suites/bot-filtering/ | G17: Bot Filtering in Adobe Analytics | H17: Yes | I17: How Adobe Analytics removes automated, non-human traffic before it is counted: the IAB bot list, custom bot rules, and what filtering does and does not clean. | J17: Yes | K17: 32 | L17: 158 | M17: No | N17: No | O17: =IF(AND(H17="Yes",J17="Yes",M17="Yes",N17="Yes"),"Yes","No")
A18: Foundations | B18: report-suites | C18: 7 | D18: Privacy and Data Retention | E18: Section | F18: /adobe-analytics-learning/foundations/report-suites/privacy-data-retention/ | G18: Privacy and Data Retention in Adobe Analytics | H18: Yes | I18: How Adobe Analytics governs personal data: data retention periods, IP obfuscation, and the labeling that supports GDPR and CCPA compliance. | J18: Yes | K18: 45 | L18: 139 | M18: No | N18: No | O18: =IF(AND(H18="Yes",J18="Yes",M18="Yes",N18="Yes"),"Yes","No")
A19: Foundations | B19: report-suites | C19: 8 | D19: Report Suite Best Practices | E19: Section | F19: /adobe-analytics-learning/foundations/report-suites/best-practices/ | G19: Report Suite Best Practices in Adobe Analytics | H19: Yes | I19: Naming conventions, mirrored production and non-production suites, foundational variables before go-live, and why documentation is the organization's decision. | J19: Yes | K19: 46 | L19: 159 | M19: Yes | N19: Yes | O19: =IF(AND(H19="Yes",J19="Yes",M19="Yes",N19="Yes"),"Yes","No")
A20: Foundations | B20: variables | D20: Variables: Props, eVars, and Events | E20: Module landing | F20: /adobe-analytics-learning/foundations/variables/ | G20: Adobe Analytics Variables: Props, eVars, Events | H20: Yes | I20: Props, eVars, events, the products string, and list variables. What each one is for, and the traps that quietly corrupt your data. | J20: Yes | K20: 47 | L20: 130 | M20: No | N20: No | O20: =IF(AND(H20="Yes",J20="Yes",M20="Yes",N20="Yes"),"Yes","No")
A21: Foundations | B21: variables | C21: 1 | D21: Props (Traffic Variables) | E21: Section | F21: /adobe-analytics-learning/foundations/variables/props-traffic-variables/ | G21: Props (Traffic Variables) in Adobe Analytics | H21: Yes | I21: Props are traffic variables, written in pencil. What they are for, their capacity and limits, and the two jobs they are quietly better at than eVars. | J21: Yes | K21: 44 | L21: 149 | M21: Yes | N21: Yes | O21: =IF(AND(H21="Yes",J21="Yes",M21="Yes",N21="Yes"),"Yes","No")
A22: Foundations | B22: variables | C22: 2 | D22: eVars (Conversion Variables) | E22: Section | F22: /adobe-analytics-learning/foundations/variables/evars-conversion-variables/ | G22: eVars (Conversion Variables) in Adobe Analytics | H22: Yes | I22: eVars persist, and persistence is the whole point. Expiration, allocation, merchandising eVars, and who actually gets the credit for a conversion. | J22: Yes | K22: 47 | L22: 146 | M22: Yes | N22: Yes | O22: =IF(AND(H22="Yes",J22="Yes",M22="Yes",N22="Yes"),"Yes","No")
A23: Foundations | B23: variables | C23: 3 | D23: Events (Success Events) | E23: Section | F23: /adobe-analytics-learning/foundations/variables/events-success-events/ | G23: Success Events in Adobe Analytics | H23: Yes | I23: Success events count the things that matter. Counter, numeric, and currency events, serialization to stop double-counting, and the setting you need to know. | J23: Yes | K23: 33 | L23: 156 | M23: Yes | N23: Yes | O23: =IF(AND(H23="Yes",J23="Yes",M23="Yes",N23="Yes"),"Yes","No")
A24: Foundations | B24: variables | C24: 4 | D24: Default and Reserved Variables | E24: Section | F24: /adobe-analytics-learning/foundations/variables/default-reserved-variables/ | G24: Default and Reserved Variables in Adobe Analytics | H24: Yes | I24: pageName, campaign, and the reserved variables Adobe fills for you. Small variables with big consequences, and the two IDs people constantly mix up. | J24: Yes | K24: 49 | L24: 148 | M24: Yes | N24: Yes | O24: =IF(AND(H24="Yes",J24="Yes",M24="Yes",N24="Yes"),"Yes","No")
A25: Foundations | B25: variables | C25: 5 | D25: The Products String | E25: Section | F25: /adobe-analytics-learning/foundations/variables/products-string/ | G25: The Adobe Analytics Products String | H25: Yes | I25: The products variable runs your whole ecommerce funnel through one string. Its six positions, its three delimiters, and the traps that corrupt commerce data. | J25: Yes | K25: 35 | L25: 157 | M25: Yes | N25: Yes | O25: =IF(AND(H25="Yes",J25="Yes",M25="Yes",N25="Yes"),"Yes","No")
A26: Foundations | B26: variables | C26: 6 | D26: List Variables and List Props | E26: Section | F26: /adobe-analytics-learning/foundations/variables/list-variables-list-props/ | G26: List Variables and List Props in Adobe Analytics | H26: Yes | I26: List variables and list props hold several values in one hit. What each is for, the settings worth knowing, and why you have to guard your three. | J26: Yes | K26: 48 | L26: 145 | M26: Yes | N26: Yes | O26: =IF(AND(H26="Yes",J26="Yes",M26="Yes",N26="Yes"),"Yes","No")
A27: Foundations | B27: variables | C27: 7 | D27: Context Data Variables | E27: Section | F27: /adobe-analytics-learning/foundations/variables/context-data-variables/ | G27: Context Data Variables in Adobe Analytics | H27: Yes | I27: Context data variables let you send data without spending a variable slot. What it buys you, why it is not optional on mobile, and where this is heading. | J27: Yes | K27: 41 | L27: 153 | M27: Yes | N27: Yes | O27: =IF(AND(H27="Yes",J27="Yes",M27="Yes",N27="Yes"),"Yes","No")
A28: Foundations | B28: variables | C28: 8 | D28: Variable Planning | E28: Section | F28: /adobe-analytics-learning/foundations/variables/variable-planning/ | G28: Adobe Analytics Variable Planning and the SDR | H28: Yes | I28: Start from the report you want, not from the variables. The planning process step by step, and the solution design reference that holds it together. | J28: Yes | K28: 45 | L28: 148 | M28: Yes | N28: Yes | O28: =IF(AND(H28="Yes",J28="Yes",M28="Yes",N28="Yes"),"Yes","No")
A29: Collect | D29: Collect the data | E29: Category landing | F29: /adobe-analytics-learning/collect/ | G29: Collecting Data in Adobe Analytics | H29: Yes | I29: How data gets from a page or app into Adobe: the collection methods, the data layer that feeds them, the tag manager that fires them, and the tracking calls that carry the payload. | J29: Yes | K29: 34 | L29: 180 | M29: No | N29: No | O29: =IF(AND(H29="Yes",J29="Yes",M29="Yes",N29="Yes"),"Yes","No")
A30: Collect | B30: adobe-launch-tags | D30: Adobe Launch (Tags) | E30: Module landing | F30: /adobe-analytics-learning/collect/adobe-launch-tags/ | G30: Adobe Launch (Tags) for Analytics | H30: Yes | I30: Adobe Experience Platform Tags, formerly Launch. Properties, extensions, data elements, rules, and the publishing workflow that keeps production safe. | J30: Yes | K30: 33 | L30: 150 | M30: No | N30: No | O30: =IF(AND(H30="Yes",J30="Yes",M30="Yes",N30="Yes"),"Yes","No")
A31: Collect | B31: adobe-launch-tags | C31: 1 | D31: Launch Architecture | E31: Section | F31: /adobe-analytics-learning/collect/adobe-launch-tags/launch-architecture/ | H31: No | I31: What Launch actually is, why Adobe built it rather than leaving you on Tealium or Google Tag Manager, and how it is organized. | J31: Yes | K31: 0 | L31: 126 | M31: Yes | N31: Yes | O31: Locked
A32: Collect | B32: adobe-launch-tags | C32: 2 | D32: Properties | E32: Section | F32: /adobe-analytics-learning/collect/adobe-launch-tags/properties/ | H32: No | I32: A property is one script, one scope, one team. What it holds, why property design matters more than it looks, and the _satellite object underneath. | J32: Yes | K32: 0 | L32: 147 | M32: Yes | N32: Yes | O32: Locked
A33: Collect | B33: adobe-launch-tags | C33: 3 | D33: Extensions | E33: Section | F33: /adobe-analytics-learning/collect/adobe-launch-tags/extensions/ | H33: No | I33: Extensions are how Launch becomes a platform rather than a script loader. What an extension really is, its anatomy, and why Adobe put its own products in it. | J33: Yes | K33: 0 | L33: 157 | M33: Yes | N33: Yes | O33: Locked
A34: Collect | B34: adobe-launch-tags | C34: 4 | D34: Data Elements | E34: Section | F34: /adobe-analytics-learning/collect/adobe-launch-tags/data-elements/ | H34: No | I34: A data element is not just a variable, it carries capability. How it differs from the data layer, the types available, and why bypassing it costs you. | J34: Yes | K34: 0 | L34: 150 | M34: Yes | N34: Yes | O34: Locked
A35: Collect | B35: adobe-launch-tags | C35: 5 | D35: Rules | E35: Section | F35: /adobe-analytics-learning/collect/adobe-launch-tags/rules/ | H35: No | I35: Every Launch rule has three parts: events, conditions, and actions. What each one decides, and how rule sequence makes several rules work together. | J35: Yes | K35: 0 | L35: 147 | M35: Yes | N35: Yes | O35: Locked
A36: Collect | B36: adobe-launch-tags | C36: 6 | D36: Publishing Workflow | E36: Section | F36: /adobe-analytics-learning/collect/adobe-launch-tags/publishing-workflow/ | H36: No | I36: The four states a library moves through, the approval gates and why they exist, publishing day, and what to do when production goes wrong. | J36: Yes | K36: 0 | L36: 138 | M36: Yes | N36: Yes | O36: Locked
A37: Collect | B37: adobe-launch-tags | C37: 7 | D37: Environments | E37: Section | F37: /adobe-analytics-learning/collect/adobe-launch-tags/environments/ | G37: Environments and Embed Codes in Adobe Launch | H37: Yes | I37: Why Launch has development, staging, and production environments, why the last two are singular, and why you cannot edit them directly. | J37: Yes | K37: 44 | L37: 135 | M37: Yes | N37: Yes | O37: Locked
A38: Collect | B38: adobe-launch-tags | C38: 8 | D38: Consent and Tag Management | E38: Section | F38: /adobe-analytics-learning/collect/adobe-launch-tags/consent-and-tag-management/ | G38: Consent Management in Adobe Launch | H38: Yes | I38: This section is not yet written. | J38: Yes | K38: 34 | L38: 32 | M38: No | N38: No | O38: =IF(AND(H38="Yes",J38="Yes",M38="Yes",N38="Yes"),"Yes","No")
A39: Collect | B39: data-collection | D39: Data Collection | E39: Module landing | F39: /adobe-analytics-learning/collect/data-collection/ | G39: Data Collection in Adobe Analytics | H39: Yes | I39: How data actually gets from a browser or an app into Adobe Analytics: AppMeasurement, the Web SDK, server-side, mobile, and the data layer underneath. | J39: Yes | K39: 34 | L39: 150 | M39: No | N39: No | O39: =IF(AND(H39="Yes",J39="Yes",M39="Yes",N39="Yes"),"Yes","No")
A40: Collect | B40: data-collection | C40: 1 | D40: Collection Methods Overview | E40: Section | F40: /adobe-analytics-learning/collect/data-collection/collection-methods-overview/ | H40: No | I40: The four ways to capture data, the two questions that define every implementation, and how teams actually choose between them. | J40: Yes | K40: 0 | L40: 126 | M40: Yes | N40: Yes | O40: Locked
...

Sheet Summary
A1: Adobe Analytics Learning — Completion Tracker
A2: Generated from the live build. 144 real pages (alias/redirect stubs excluded). Content-complete = the 66 sections in the 12 modules through Segments. Regenerate at each module sign-off.
A4: Metric | B4: Done | C4: Total | D4: Percent
A5: SEO title complete | B5: =COUNTIF(Pages!H2:H145,"Yes") | C5: 144 | D5: =B5/C5
A6: SEO description complete | B6: =COUNTIF(Pages!J2:J145,"Yes") | C6: 144 | D6: =B6/C6
A7: Content created | B7: =COUNTIF(Pages!M2:M145,"Yes") | C7: 144 | D7: =B7/C7
A8: Content QA'd (approved) | B8: =COUNTIF(Pages!N2:N145,"Yes") | C8: 144 | D8: =B8/C8
A9: Final result (fully done) | B9: =COUNTIF(Pages!O2:O145,"Yes") | C9: 144 | D9: =B9/C9
A11: Per phase (all page types)
A12: Phase | B12: Pages | C12: Content created | D12: QA'd | E12: Fully done | F12: Done %
A13: Foundations | B13: =COUNTIF(Pages!A2:A145,"Foundations") | C13: =COUNTIFS(Pages!A2:A145,"Foundations",Pages!M2:M145,"Yes") | D13: =COUNTIFS(Pages!A2:A145,"Foundations",Pages!N2:N145,"Yes") | E13: =COUNTIFS(Pages!A2:A145,"Foundations",Pages!O2:O145,"Yes") | F13: =IF(B13=0,0,E13/B13)
A14: Collect | B14: =COUNTIF(Pages!A2:A145,"Collect") | C14: =COUNTIFS(Pages!A2:A145,"Collect",Pages!M2:M145,"Yes") | D14: =COUNTIFS(Pages!A2:A145,"Collect",Pages!N2:N145,"Yes") | E14: =COUNTIFS(Pages!A2:A145,"Collect",Pages!O2:O145,"Yes") | F14: =IF(B14=0,0,E14/B14)
A15: Shape | B15: =COUNTIF(Pages!A2:A145,"Shape") | C15: =COUNTIFS(Pages!A2:A145,"Shape",Pages!M2:M145,"Yes") | D15: =COUNTIFS(Pages!A2:A145,"Shape",Pages!N2:N145,"Yes") | E15: =COUNTIFS(Pages!A2:A145,"Shape",Pages!O2:O145,"Yes") | F15: =IF(B15=0,0,E15/B15)
A16: Analyze | B16: =COUNTIF(Pages!A2:A145,"Analyze") | C16: =COUNTIFS(Pages!A2:A145,"Analyze",Pages!M2:M145,"Yes") | D16: =COUNTIFS(Pages!A2:A145,"Analyze",Pages!N2:N145,"Yes") | E16: =COUNTIFS(Pages!A2:A145,"Analyze",Pages!O2:O145,"Yes") | F16: =IF(B16=0,0,E16/B16)
A17: Deliver | B17: =COUNTIF(Pages!A2:A145,"Deliver") | C17: =COUNTIFS(Pages!A2:A145,"Deliver",Pages!M2:M145,"Yes") | D17: =COUNTIFS(Pages!A2:A145,"Deliver",Pages!N2:N145,"Yes") | E17: =COUNTIFS(Pages!A2:A145,"Deliver",Pages!O2:O145,"Yes") | F17: =IF(B17=0,0,E17/B17)
